[2025-06-18T16:41:54.103+0000] {local_task_job_runner.py:120} INFO - ::group::Pre task execution logs
[2025-06-18T16:41:54.270+0000] {taskinstance.py:2076} INFO - Dependencies all met for dep_context=non-requeueable deps ti=<TaskInstance: nba_etl_to_postgres.fetch_schedule_and_load_to_postgres manual__2025-06-18T16:41:51.721509+00:00 [queued]>
[2025-06-18T16:41:55.174+0000] {taskinstance.py:2076} INFO - Dependencies all met for dep_context=requeueable deps ti=<TaskInstance: nba_etl_to_postgres.fetch_schedule_and_load_to_postgres manual__2025-06-18T16:41:51.721509+00:00 [queued]>
[2025-06-18T16:41:55.176+0000] {taskinstance.py:2306} INFO - Starting attempt 1 of 2
[2025-06-18T16:41:55.265+0000] {taskinstance.py:2330} INFO - Executing <Task(PythonOperator): fetch_schedule_and_load_to_postgres> on 2025-06-18 16:41:51.721509+00:00
[2025-06-18T16:41:55.276+0000] {standard_task_runner.py:63} INFO - Started process 1168 to run task
[2025-06-18T16:41:55.282+0000] {standard_task_runner.py:90} INFO - Running: ['***', 'tasks', 'run', 'nba_etl_to_postgres', 'fetch_schedule_and_load_to_postgres', 'manual__2025-06-18T16:41:51.721509+00:00', '--job-id', '60', '--raw', '--subdir', 'DAGS_FOLDER/etl_pipeline.py', '--cfg-path', '/tmp/tmp2evicyl9']
[2025-06-18T16:41:55.284+0000] {standard_task_runner.py:91} INFO - Job 60: Subtask fetch_schedule_and_load_to_postgres
[2025-06-18T16:41:55.433+0000] {task_command.py:426} INFO - Running <TaskInstance: nba_etl_to_postgres.fetch_schedule_and_load_to_postgres manual__2025-06-18T16:41:51.721509+00:00 [running]> on host 11d91b3c2b82
[2025-06-18T16:41:55.664+0000] {taskinstance.py:2648} INFO - Exporting env vars: AIRFLOW_CTX_DAG_OWNER='***' AIRFLOW_CTX_DAG_ID='nba_etl_to_postgres' AIRFLOW_CTX_TASK_ID='fetch_schedule_and_load_to_postgres' AIRFLOW_CTX_EXECUTION_DATE='2025-06-18T16:41:51.721509+00:00' AIRFLOW_CTX_TRY_NUMBER='1' AIRFLOW_CTX_DAG_RUN_ID='manual__2025-06-18T16:41:51.721509+00:00'
[2025-06-18T16:41:55.665+0000] {taskinstance.py:430} INFO - ::endgroup::
[2025-06-18T16:41:55.736+0000] {logging_mixin.py:188} INFO - Fetching schedule from NBA API...
[2025-06-18T16:41:59.744+0000] {logging_mixin.py:188} INFO - Failed to fetch data from NBA API: HTTPSConnectionPool(host='cdn.nba.com', port=443): Max retries exceeded with url: /static/json/staticData/scheduleLeague+V2.json (Caused by NameResolutionError("<urllib3.connection.HTTPSConnection object at 0x7bd6baf69fd0>: Failed to resolve 'cdn.nba.com' ([Errno -2] Name or service not known)"))
[2025-06-18T16:41:59.745+0000] {taskinstance.py:441} INFO - ::group::Post task execution logs
[2025-06-18T16:41:59.746+0000] {taskinstance.py:2905} ERROR - Task failed with exception
Traceback (most recent call last):
  File "/home/airflow/.local/lib/python3.9/site-packages/urllib3/connection.py", line 198, in _new_conn
    sock = connection.create_connection(
  File "/home/airflow/.local/lib/python3.9/site-packages/urllib3/util/connection.py", line 60, in create_connection
    for res in socket.getaddrinfo(host, port, family, socket.SOCK_STREAM):
  File "/usr/local/lib/python3.9/socket.py", line 954, in getaddrinfo
    for res in _socket.getaddrinfo(host, port, family, type, proto, flags):
socket.gaierror: [Errno -2] Name or service not known

The above exception was the direct cause of the following exception:

Traceback (most recent call last):
  File "/home/airflow/.local/lib/python3.9/site-packages/urllib3/connectionpool.py", line 787, in urlopen
    response = self._make_request(
  File "/home/airflow/.local/lib/python3.9/site-packages/urllib3/connectionpool.py", line 488, in _make_request
    raise new_e
  File "/home/airflow/.local/lib/python3.9/site-packages/urllib3/connectionpool.py", line 464, in _make_request
    self._validate_conn(conn)
  File "/home/airflow/.local/lib/python3.9/site-packages/urllib3/connectionpool.py", line 1093, in _validate_conn
    conn.connect()
  File "/home/airflow/.local/lib/python3.9/site-packages/urllib3/connection.py", line 704, in connect
    self.sock = sock = self._new_conn()
  File "/home/airflow/.local/lib/python3.9/site-packages/urllib3/connection.py", line 205, in _new_conn
    raise NameResolutionError(self.host, self, e) from e
urllib3.exceptions.NameResolutionError: <urllib3.connection.HTTPSConnection object at 0x7bd6baf69fd0>: Failed to resolve 'cdn.nba.com' ([Errno -2] Name or service not known)

The above exception was the direct cause of the following exception:

Traceback (most recent call last):
  File "/home/airflow/.local/lib/python3.9/site-packages/requests/adapters.py", line 486, in send
    resp = conn.urlopen(
  File "/home/airflow/.local/lib/python3.9/site-packages/urllib3/connectionpool.py", line 841, in urlopen
    retries = retries.increment(
  File "/home/airflow/.local/lib/python3.9/site-packages/urllib3/util/retry.py", line 519, in increment
    raise MaxRetryError(_pool, url, reason) from reason  # type: ignore[arg-type]
urllib3.exceptions.MaxRetryError: HTTPSConnectionPool(host='cdn.nba.com', port=443): Max retries exceeded with url: /static/json/staticData/scheduleLeague+V2.json (Caused by NameResolutionError("<urllib3.connection.HTTPSConnection object at 0x7bd6baf69fd0>: Failed to resolve 'cdn.nba.com' ([Errno -2] Name or service not known)"))

During handling of the above exception, another exception occurred:

Traceback (most recent call last):
  File "/home/airflow/.local/lib/python3.9/site-packages/airflow/models/taskinstance.py", line 465, in _execute_task
    result = _execute_callable(context=context, **execute_callable_kwargs)
  File "/home/airflow/.local/lib/python3.9/site-packages/airflow/models/taskinstance.py", line 432, in _execute_callable
    return execute_callable(context=context, **execute_callable_kwargs)
  File "/home/airflow/.local/lib/python3.9/site-packages/airflow/models/baseoperator.py", line 400, in wrapper
    return func(self, *args, **kwargs)
  File "/home/airflow/.local/lib/python3.9/site-packages/airflow/operators/python.py", line 235, in execute
    return_value = self.execute_callable()
  File "/home/airflow/.local/lib/python3.9/site-packages/airflow/operators/python.py", line 252, in execute_callable
    return self.python_callable(*self.op_args, **self.op_kwargs)
  File "/opt/airflow/dags/etl_pipeline.py", line 90, in fetch_and_load_schedule_to_stage
    res = requests.get(url)
  File "/home/airflow/.local/lib/python3.9/site-packages/requests/api.py", line 73, in get
    return request("get", url, params=params, **kwargs)
  File "/home/airflow/.local/lib/python3.9/site-packages/requests/api.py", line 59, in request
    return session.request(method=method, url=url, **kwargs)
  File "/home/airflow/.local/lib/python3.9/site-packages/requests/sessions.py", line 589, in request
    resp = self.send(prep, **send_kwargs)
  File "/home/airflow/.local/lib/python3.9/site-packages/requests/sessions.py", line 703, in send
    r = adapter.send(request, **kwargs)
  File "/home/airflow/.local/lib/python3.9/site-packages/requests/adapters.py", line 519, in send
    raise ConnectionError(e, request=request)
requests.exceptions.ConnectionError: HTTPSConnectionPool(host='cdn.nba.com', port=443): Max retries exceeded with url: /static/json/staticData/scheduleLeague+V2.json (Caused by NameResolutionError("<urllib3.connection.HTTPSConnection object at 0x7bd6baf69fd0>: Failed to resolve 'cdn.nba.com' ([Errno -2] Name or service not known)"))
[2025-06-18T16:41:59.886+0000] {taskinstance.py:1206} INFO - Marking task as UP_FOR_RETRY. dag_id=nba_etl_to_postgres, task_id=fetch_schedule_and_load_to_postgres, run_id=manual__2025-06-18T16:41:51.721509+00:00, execution_date=20250618T164151, start_date=20250618T164154, end_date=20250618T164159
[2025-06-18T16:41:59.950+0000] {standard_task_runner.py:110} ERROR - Failed to execute job 60 for task fetch_schedule_and_load_to_postgres (HTTPSConnectionPool(host='cdn.nba.com', port=443): Max retries exceeded with url: /static/json/staticData/scheduleLeague+V2.json (Caused by NameResolutionError("<urllib3.connection.HTTPSConnection object at 0x7bd6baf69fd0>: Failed to resolve 'cdn.nba.com' ([Errno -2] Name or service not known)")); 1168)
[2025-06-18T16:41:59.987+0000] {local_task_job_runner.py:240} INFO - Task exited with return code 1
[2025-06-18T16:42:00.010+0000] {taskinstance.py:3498} INFO - 0 downstream tasks scheduled from follow-on schedule check
[2025-06-18T16:42:00.035+0000] {local_task_job_runner.py:222} INFO - ::endgroup::
