[2025-06-15T20:01:43.662+0000] {local_task_job_runner.py:120} INFO - ::group::Pre task execution logs
[2025-06-15T20:01:43.691+0000] {taskinstance.py:2076} INFO - Dependencies all met for dep_context=non-requeueable deps ti=<TaskInstance: nba_staging_to_dwh.transform_load_dim_match scheduled__2025-06-08T00:00:00+00:00 [queued]>
[2025-06-15T20:01:43.699+0000] {taskinstance.py:2076} INFO - Dependencies all met for dep_context=requeueable deps ti=<TaskInstance: nba_staging_to_dwh.transform_load_dim_match scheduled__2025-06-08T00:00:00+00:00 [queued]>
[2025-06-15T20:01:43.700+0000] {taskinstance.py:2306} INFO - Starting attempt 2 of 2
[2025-06-15T20:01:43.769+0000] {taskinstance.py:2330} INFO - Executing <Task(PythonOperator): transform_load_dim_match> on 2025-06-08 00:00:00+00:00
[2025-06-15T20:01:43.798+0000] {standard_task_runner.py:63} INFO - Started process 897 to run task
[2025-06-15T20:01:43.815+0000] {standard_task_runner.py:90} INFO - Running: ['***', 'tasks', 'run', 'nba_staging_to_dwh', 'transform_load_dim_match', 'scheduled__2025-06-08T00:00:00+00:00', '--job-id', '53', '--raw', '--subdir', 'DAGS_FOLDER/etl_pipeline.py', '--cfg-path', '/tmp/tmpx6qstgp3']
[2025-06-15T20:01:43.821+0000] {standard_task_runner.py:91} INFO - Job 53: Subtask transform_load_dim_match
[2025-06-15T20:01:44.012+0000] {task_command.py:426} INFO - Running <TaskInstance: nba_staging_to_dwh.transform_load_dim_match scheduled__2025-06-08T00:00:00+00:00 [running]> on host ca2a611cae31
[2025-06-15T20:01:44.169+0000] {taskinstance.py:2648} INFO - Exporting env vars: AIRFLOW_CTX_DAG_OWNER='***' AIRFLOW_CTX_DAG_ID='nba_staging_to_dwh' AIRFLOW_CTX_TASK_ID='transform_load_dim_match' AIRFLOW_CTX_EXECUTION_DATE='2025-06-08T00:00:00+00:00' AIRFLOW_CTX_TRY_NUMBER='2' AIRFLOW_CTX_DAG_RUN_ID='scheduled__2025-06-08T00:00:00+00:00'
[2025-06-15T20:01:44.170+0000] {taskinstance.py:430} INFO - ::endgroup::
[2025-06-15T20:01:44.199+0000] {logging_mixin.py:188} WARNING - /opt/***/dags/etl_pipeline.py:313 UserWarning: pandas only supports SQLAlchemy connectable (engine/connection) or database string URI or sqlite3 DBAPI2 connection. Other DBAPI2 objects are not tested. Please consider using SQLAlchemy.
[2025-06-15T20:01:44.236+0000] {logging_mixin.py:188} INFO - Ensuring table 'DimMatch' exists...
[2025-06-15T20:01:44.237+0000] {logging_mixin.py:188} INFO - Table 'DimMatch' is ready.
[2025-06-15T20:01:44.249+0000] {logging_mixin.py:188} INFO - Loading 10568 rows into DimMatch...
[2025-06-15T20:01:44.252+0000] {logging_mixin.py:188} INFO - Database execution error: column "date" of relation "dimmatch" does not exist
LINE 1: INSERT INTO DimMatch ("hometeam", "awayteam", "date", "arena...
                                                      ^
[2025-06-15T20:01:44.252+0000] {taskinstance.py:441} INFO - ::group::Post task execution logs
[2025-06-15T20:01:44.253+0000] {taskinstance.py:2905} ERROR - Task failed with exception
Traceback (most recent call last):
  File "/home/airflow/.local/lib/python3.9/site-packages/airflow/models/taskinstance.py", line 465, in _execute_task
    result = _execute_callable(context=context, **execute_callable_kwargs)
  File "/home/airflow/.local/lib/python3.9/site-packages/airflow/models/taskinstance.py", line 432, in _execute_callable
    return execute_callable(context=context, **execute_callable_kwargs)
  File "/home/airflow/.local/lib/python3.9/site-packages/airflow/models/baseoperator.py", line 400, in wrapper
    return func(self, *args, **kwargs)
  File "/home/airflow/.local/lib/python3.9/site-packages/airflow/operators/python.py", line 235, in execute
    return_value = self.execute_callable()
  File "/home/airflow/.local/lib/python3.9/site-packages/airflow/operators/python.py", line 252, in execute_callable
    return self.python_callable(*self.op_args, **self.op_kwargs)
  File "/opt/airflow/dags/etl_pipeline.py", line 346, in dim_match_transform_load
    load_df_to_postgres(df=df, table_name=table_name, conn_string=conn_string, create_table_query=create_table_query)
  File "/opt/airflow/dags/etl_pipeline.py", line 63, in load_df_to_postgres
    execute_values(cursor, sql_query, data_tuples)
  File "/home/airflow/.local/lib/python3.9/site-packages/psycopg2/extras.py", line 1299, in execute_values
    cur.execute(b''.join(parts))
psycopg2.errors.UndefinedColumn: column "date" of relation "dimmatch" does not exist
LINE 1: INSERT INTO DimMatch ("hometeam", "awayteam", "date", "arena...
                                                      ^

[2025-06-15T20:01:44.333+0000] {taskinstance.py:1206} INFO - Marking task as FAILED. dag_id=nba_staging_to_dwh, task_id=transform_load_dim_match, run_id=scheduled__2025-06-08T00:00:00+00:00, execution_date=20250608T000000, start_date=20250615T200143, end_date=20250615T200144
[2025-06-15T20:01:44.392+0000] {standard_task_runner.py:110} ERROR - Failed to execute job 53 for task transform_load_dim_match (column "date" of relation "dimmatch" does not exist
LINE 1: INSERT INTO DimMatch ("hometeam", "awayteam", "date", "arena...
                                                      ^
; 897)
[2025-06-15T20:01:44.433+0000] {local_task_job_runner.py:240} INFO - Task exited with return code 1
[2025-06-15T20:01:44.453+0000] {taskinstance.py:3498} INFO - 0 downstream tasks scheduled from follow-on schedule check
[2025-06-15T20:01:44.486+0000] {local_task_job_runner.py:222} INFO - ::endgroup::
[2025-06-15T20:38:29.842+0000] {local_task_job_runner.py:120} INFO - ::group::Pre task execution logs
[2025-06-15T20:38:29.886+0000] {taskinstance.py:2076} INFO - Dependencies all met for dep_context=non-requeueable deps ti=<TaskInstance: nba_staging_to_dwh.transform_load_dim_match scheduled__2025-06-08T00:00:00+00:00 [queued]>
[2025-06-15T20:38:29.900+0000] {taskinstance.py:2076} INFO - Dependencies all met for dep_context=requeueable deps ti=<TaskInstance: nba_staging_to_dwh.transform_load_dim_match scheduled__2025-06-08T00:00:00+00:00 [queued]>
[2025-06-15T20:38:29.901+0000] {taskinstance.py:2306} INFO - Starting attempt 2 of 2
[2025-06-15T20:38:30.092+0000] {taskinstance.py:2330} INFO - Executing <Task(PythonOperator): transform_load_dim_match> on 2025-06-08 00:00:00+00:00
[2025-06-15T20:38:30.213+0000] {standard_task_runner.py:63} INFO - Started process 882 to run task
[2025-06-15T20:38:30.861+0000] {standard_task_runner.py:90} INFO - Running: ['***', 'tasks', 'run', 'nba_staging_to_dwh', 'transform_load_dim_match', 'scheduled__2025-06-08T00:00:00+00:00', '--job-id', '11', '--raw', '--subdir', 'DAGS_FOLDER/etl_pipeline.py', '--cfg-path', '/tmp/tmpsvo1jt2x']
[2025-06-15T20:38:30.863+0000] {standard_task_runner.py:91} INFO - Job 11: Subtask transform_load_dim_match
[2025-06-15T20:38:33.424+0000] {task_command.py:426} INFO - Running <TaskInstance: nba_staging_to_dwh.transform_load_dim_match scheduled__2025-06-08T00:00:00+00:00 [running]> on host 1c61638087f1
[2025-06-15T20:38:39.439+0000] {taskinstance.py:2648} INFO - Exporting env vars: AIRFLOW_CTX_DAG_OWNER='***' AIRFLOW_CTX_DAG_ID='nba_staging_to_dwh' AIRFLOW_CTX_TASK_ID='transform_load_dim_match' AIRFLOW_CTX_EXECUTION_DATE='2025-06-08T00:00:00+00:00' AIRFLOW_CTX_TRY_NUMBER='2' AIRFLOW_CTX_DAG_RUN_ID='scheduled__2025-06-08T00:00:00+00:00'
[2025-06-15T20:38:39.441+0000] {taskinstance.py:430} INFO - ::endgroup::
[2025-06-15T20:38:39.484+0000] {logging_mixin.py:188} WARNING - /opt/***/dags/etl_pipeline.py:313 UserWarning: pandas only supports SQLAlchemy connectable (engine/connection) or database string URI or sqlite3 DBAPI2 connection. Other DBAPI2 objects are not tested. Please consider using SQLAlchemy.
[2025-06-15T20:38:39.506+0000] {logging_mixin.py:188} INFO - Ensuring table 'DimMatch' exists...
[2025-06-15T20:38:39.508+0000] {logging_mixin.py:188} INFO - Table 'DimMatch' is ready.
[2025-06-15T20:38:39.513+0000] {logging_mixin.py:188} INFO - Loading 2642 rows into DimMatch...
[2025-06-15T20:38:39.517+0000] {logging_mixin.py:188} INFO - Database execution error: column "date" of relation "dimmatch" does not exist
LINE 1: INSERT INTO DimMatch ("hometeam", "awayteam", "date", "arena...
                                                      ^
[2025-06-15T20:38:39.519+0000] {taskinstance.py:441} INFO - ::group::Post task execution logs
[2025-06-15T20:38:39.520+0000] {taskinstance.py:2905} ERROR - Task failed with exception
Traceback (most recent call last):
  File "/home/airflow/.local/lib/python3.9/site-packages/airflow/models/taskinstance.py", line 465, in _execute_task
    result = _execute_callable(context=context, **execute_callable_kwargs)
  File "/home/airflow/.local/lib/python3.9/site-packages/airflow/models/taskinstance.py", line 432, in _execute_callable
    return execute_callable(context=context, **execute_callable_kwargs)
  File "/home/airflow/.local/lib/python3.9/site-packages/airflow/models/baseoperator.py", line 400, in wrapper
    return func(self, *args, **kwargs)
  File "/home/airflow/.local/lib/python3.9/site-packages/airflow/operators/python.py", line 235, in execute
    return_value = self.execute_callable()
  File "/home/airflow/.local/lib/python3.9/site-packages/airflow/operators/python.py", line 252, in execute_callable
    return self.python_callable(*self.op_args, **self.op_kwargs)
  File "/opt/airflow/dags/etl_pipeline.py", line 346, in dim_match_transform_load
    load_df_to_postgres(df=df, table_name=table_name, conn_string=conn_string, create_table_query=create_table_query)
  File "/opt/airflow/dags/etl_pipeline.py", line 63, in load_df_to_postgres
    execute_values(cursor, sql_query, data_tuples)
  File "/home/airflow/.local/lib/python3.9/site-packages/psycopg2/extras.py", line 1299, in execute_values
    cur.execute(b''.join(parts))
psycopg2.errors.UndefinedColumn: column "date" of relation "dimmatch" does not exist
LINE 1: INSERT INTO DimMatch ("hometeam", "awayteam", "date", "arena...
                                                      ^

[2025-06-15T20:38:39.638+0000] {taskinstance.py:1206} INFO - Marking task as FAILED. dag_id=nba_staging_to_dwh, task_id=transform_load_dim_match, run_id=scheduled__2025-06-08T00:00:00+00:00, execution_date=20250608T000000, start_date=20250615T203829, end_date=20250615T203839
[2025-06-15T20:38:39.919+0000] {standard_task_runner.py:110} ERROR - Failed to execute job 11 for task transform_load_dim_match (column "date" of relation "dimmatch" does not exist
LINE 1: INSERT INTO DimMatch ("hometeam", "awayteam", "date", "arena...
                                                      ^
; 882)
[2025-06-15T20:38:39.952+0000] {local_task_job_runner.py:240} INFO - Task exited with return code 1
[2025-06-15T20:38:40.208+0000] {taskinstance.py:3498} INFO - 0 downstream tasks scheduled from follow-on schedule check
[2025-06-15T20:38:40.457+0000] {local_task_job_runner.py:222} INFO - ::endgroup::
