[2025-06-15T20:38:29.198+0000] {local_task_job_runner.py:120} INFO - ::group::Pre task execution logs
[2025-06-15T20:38:29.234+0000] {taskinstance.py:2076} INFO - Dependencies all met for dep_context=non-requeueable deps ti=<TaskInstance: nba_staging_to_dwh.transform_load_dim_match manual__2025-06-15T20:36:22.712725+00:00 [queued]>
[2025-06-15T20:38:29.249+0000] {taskinstance.py:2076} INFO - Dependencies all met for dep_context=requeueable deps ti=<TaskInstance: nba_staging_to_dwh.transform_load_dim_match manual__2025-06-15T20:36:22.712725+00:00 [queued]>
[2025-06-15T20:38:29.250+0000] {taskinstance.py:2306} INFO - Starting attempt 2 of 2
[2025-06-15T20:38:29.336+0000] {taskinstance.py:2330} INFO - Executing <Task(PythonOperator): transform_load_dim_match> on 2025-06-15 20:36:22.712725+00:00
[2025-06-15T20:38:29.345+0000] {standard_task_runner.py:63} INFO - Started process 881 to run task
[2025-06-15T20:38:29.349+0000] {standard_task_runner.py:90} INFO - Running: ['***', 'tasks', 'run', 'nba_staging_to_dwh', 'transform_load_dim_match', 'manual__2025-06-15T20:36:22.712725+00:00', '--job-id', '10', '--raw', '--subdir', 'DAGS_FOLDER/etl_pipeline.py', '--cfg-path', '/tmp/tmpzbrkzjnh']
[2025-06-15T20:38:29.352+0000] {standard_task_runner.py:91} INFO - Job 10: Subtask transform_load_dim_match
[2025-06-15T20:38:29.640+0000] {task_command.py:426} INFO - Running <TaskInstance: nba_staging_to_dwh.transform_load_dim_match manual__2025-06-15T20:36:22.712725+00:00 [running]> on host 1c61638087f1
[2025-06-15T20:38:33.031+0000] {taskinstance.py:2648} INFO - Exporting env vars: AIRFLOW_CTX_DAG_OWNER='***' AIRFLOW_CTX_DAG_ID='nba_staging_to_dwh' AIRFLOW_CTX_TASK_ID='transform_load_dim_match' AIRFLOW_CTX_EXECUTION_DATE='2025-06-15T20:36:22.712725+00:00' AIRFLOW_CTX_TRY_NUMBER='2' AIRFLOW_CTX_DAG_RUN_ID='manual__2025-06-15T20:36:22.712725+00:00'
[2025-06-15T20:38:33.078+0000] {taskinstance.py:430} INFO - ::endgroup::
[2025-06-15T20:38:34.439+0000] {logging_mixin.py:188} WARNING - /opt/***/dags/etl_pipeline.py:313 UserWarning: pandas only supports SQLAlchemy connectable (engine/connection) or database string URI or sqlite3 DBAPI2 connection. Other DBAPI2 objects are not tested. Please consider using SQLAlchemy.
[2025-06-15T20:38:35.384+0000] {logging_mixin.py:188} INFO - Ensuring table 'DimMatch' exists...
[2025-06-15T20:38:37.236+0000] {logging_mixin.py:188} INFO - Table 'DimMatch' is ready.
[2025-06-15T20:38:37.443+0000] {logging_mixin.py:188} INFO - Loading 2642 rows into DimMatch...
[2025-06-15T20:38:37.447+0000] {logging_mixin.py:188} INFO - Database execution error: column "date" of relation "dimmatch" does not exist
LINE 1: INSERT INTO DimMatch ("hometeam", "awayteam", "date", "arena...
                                                      ^
[2025-06-15T20:38:37.447+0000] {taskinstance.py:441} INFO - ::group::Post task execution logs
[2025-06-15T20:38:37.448+0000] {taskinstance.py:2905} ERROR - Task failed with exception
Traceback (most recent call last):
  File "/home/airflow/.local/lib/python3.9/site-packages/airflow/models/taskinstance.py", line 465, in _execute_task
    result = _execute_callable(context=context, **execute_callable_kwargs)
  File "/home/airflow/.local/lib/python3.9/site-packages/airflow/models/taskinstance.py", line 432, in _execute_callable
    return execute_callable(context=context, **execute_callable_kwargs)
  File "/home/airflow/.local/lib/python3.9/site-packages/airflow/models/baseoperator.py", line 400, in wrapper
    return func(self, *args, **kwargs)
  File "/home/airflow/.local/lib/python3.9/site-packages/airflow/operators/python.py", line 235, in execute
    return_value = self.execute_callable()
  File "/home/airflow/.local/lib/python3.9/site-packages/airflow/operators/python.py", line 252, in execute_callable
    return self.python_callable(*self.op_args, **self.op_kwargs)
  File "/opt/airflow/dags/etl_pipeline.py", line 346, in dim_match_transform_load
    load_df_to_postgres(df=df, table_name=table_name, conn_string=conn_string, create_table_query=create_table_query)
  File "/opt/airflow/dags/etl_pipeline.py", line 63, in load_df_to_postgres
    execute_values(cursor, sql_query, data_tuples)
  File "/home/airflow/.local/lib/python3.9/site-packages/psycopg2/extras.py", line 1299, in execute_values
    cur.execute(b''.join(parts))
psycopg2.errors.UndefinedColumn: column "date" of relation "dimmatch" does not exist
LINE 1: INSERT INTO DimMatch ("hometeam", "awayteam", "date", "arena...
                                                      ^

[2025-06-15T20:38:37.814+0000] {taskinstance.py:1206} INFO - Marking task as FAILED. dag_id=nba_staging_to_dwh, task_id=transform_load_dim_match, run_id=manual__2025-06-15T20:36:22.712725+00:00, execution_date=20250615T203622, start_date=20250615T203829, end_date=20250615T203837
[2025-06-15T20:38:38.232+0000] {standard_task_runner.py:110} ERROR - Failed to execute job 10 for task transform_load_dim_match (column "date" of relation "dimmatch" does not exist
LINE 1: INSERT INTO DimMatch ("hometeam", "awayteam", "date", "arena...
                                                      ^
; 881)
[2025-06-15T20:38:38.411+0000] {local_task_job_runner.py:240} INFO - Task exited with return code 1
[2025-06-15T20:38:38.443+0000] {taskinstance.py:3498} INFO - 0 downstream tasks scheduled from follow-on schedule check
[2025-06-15T20:38:38.767+0000] {local_task_job_runner.py:222} INFO - ::endgroup::
